Workbook

Sheet MASTER DATA
A1: 2026 | B1: LEAD ADS | T1: DM | AI1: OUTBOUND - PROSPECTION | AX1: TOTAUX - NE PAS TOUCHER
B3: Dials | C3: Picked-up | D3: Call booked | E3: Rappel moi | F3: DQ | G3: Follow-Up | H3: Showed call | I3: Close | J3: Rev generated | K3: Pick up rate % | L3: Lead to set % | M3: DQ % | N3: FUP % | O3: % True convo | P3: SUR % | Q3: Close % | R3: Dials / set | S3: Rev / booking | T3: New convo | U3: New active | V3: Proposition | W3: Call booked | X3: Showed call | Y3: Close | Z3: Rev generated | AA3: % New convo | AB3: % Proposition | AC3: % P2C | AD3: % N2A | AE3: Close % | AF3: SUR % | AG3: Convo / set | AH3: Rev / booking | AI3: New convo | AJ3: New active | AK3: Proposition | AL3: Call booked | AM3: Showed call | AN3: Close | AO3: Rev generated | AP3: % New convo | AQ3: % Proposition | AR3: % P2C | AS3: % N2A | AT3: Close % | AU3: SUR % | AV3: Convo / set | AW3: Rev / booking | AX3: Call booked | AY3: Showed | AZ3: Close | BA3: Rev generated | BB3: SUR % | BC3: Close % | BD3: Rev / booking
A5: JANVIER | B5: =SUM(B26:B56) -> 0 | C5: =SUM(C26:C56) -> 0 | D5: =SUM(D26:D56) -> 0 | E5: =SUM(E26:E56) -> 0 | F5: =SUM(F26:F56) -> 0 | G5: =SUM(G26:G56) -> 0 | H5: =SUM(H26:H56) -> 0 | I5: =SUM(I26:I56) -> 0 | J5: =SUM(J26:J56) -> 0 | K5: =IFERROR(C5/B5,"") | L5: =IFERROR(D5/(C5-E5),"") | M5: =IFERROR(F5/(C5-E5),"") | N5: =IFERROR(G5/(C5-E5),"") | O5: =IFERROR((C5-E5)/C5,"") | P5: =IFERROR(H5/D5,"") | Q5: =IFERROR(I5/D5,"") | R5: =IFERROR(B5/D5,"") | S5: =IFERROR(J5/D5,"") | T5: =SUM(T26:T56) -> 0 | U5: =SUM(U26:U56) -> 0 | V5: =SUM(V26:V56) -> 0 | W5: =SUM(W26:W56) -> 0 | X5: =SUM(X26:X56) -> 0 | Y5: =SUM(Y26:Y56) -> 0 | Z5: =SUM(Z26:Z56) -> 0 | AA5: =IFERROR(U5/T5,"") | AB5: =IFERROR(V5/U5,"") | AC5: =IFERROR(W5/V5,"") | AD5: =IFERROR(W5/U5,"") | AE5: =IFERROR(Y5/W5,"") | AF5: =IFERROR(X5/W5,"") | AG5: =IFERROR(T5/W5,"") | AH5: =IFERROR(Z5/W5,"") | AI5: =SUM(AI26:AI56) -> 0 | AJ5: =SUM(AJ26:AJ56) -> 0 | AK5: =SUM(AK26:AK56) -> 0 | AL5: =SUM(AL26:AL56) -> 0 | AM5: =SUM(AM26:AM56) -> 0 | AN5: =SUM(AN26:AN56) -> 0 | AO5: =SUM(AO26:AO56) -> 0 | AP5: =IFERROR(AJ5/AI5,"") | AQ5: =IFERROR(AK5/AJ5,"") | AR5: =IFERROR(AL5/AK5,"") | AS5: =IFERROR(AL5/AJ5,"") | AT5: =IFERROR(AN5/AL5,"") | AU5: =IFERROR(AM5/AL5,"") | AV5: =IFERROR(AI5/AL5,"") | AW5: =IFERROR(AO5/AL5,"") | AX5: =SUM(AX26:AX56) -> 0 | AY5: =SUM(AY26:AY56) -> 0 | AZ5: =SUM(AZ26:AZ56) -> 0 | BA5: =SUM(BA26:BA56) -> 0 | BB5: =IFERROR(AY5/AX5,"") | BC5: =IFERROR(AZ5/AX5,"") | BD5: =IFERROR(BA5/AX5,"")
A6: FÉVRIER | B6: =SUM(B58:B86) -> 0 | C6: =SUM(C58:C86) -> 0 | D6: =SUM(D58:D86) -> 0 | E6: =SUM(E58:E86) -> 0 | F6: =SUM(F58:F86) -> 0 | G6: =SUM(G58:G86) -> 0 | H6: =SUM(H58:H86) -> 0 | I6: =SUM(I58:I86) -> 0 | J6: =SUM(J58:J86) -> 0 | K6: =IFERROR(C6/B6,"") | L6: =IFERROR(D6/(C6-E6),"") | M6: =IFERROR(F6/(C6-E6),"") | N6: =IFERROR(G6/(C6-E6),"") | O6: =IFERROR((C6-E6)/C6,"") | P6: =IFERROR(H6/D6,"") | Q6: =IFERROR(I6/D6,"") | R6: =IFERROR(B6/D6,"") | S6: =IFERROR(J6/D6,"") | T6: =SUM(T58:T86) -> 0 | U6: =SUM(U58:U86) -> 0 | V6: =SUM(V58:V86) -> 0 | W6: =SUM(W58:W86) -> 0 | X6: =SUM(X58:X86) -> 0 | Y6: =SUM(Y58:Y86) -> 0 | Z6: =SUM(Z58:Z86) -> 0 | AA6: =IFERROR(U6/T6,"") | AB6: =IFERROR(V6/U6,"") | AC6: =IFERROR(W6/V6,"") | AD6: =IFERROR(W6/U6,"") | AE6: =IFERROR(Y6/W6,"") | AF6: =IFERROR(X6/W6,"") | AG6: =IFERROR(T6/W6,"") | AH6: =IFERROR(Z6/W6,"") | AI6: =SUM(AI58:AI86) -> 0 | AJ6: =SUM(AJ58:AJ86) -> 0 | AK6: =SUM(AK58:AK86) -> 0 | AL6: =SUM(AL58:AL86) -> 0 | AM6: =SUM(AM58:AM86) -> 0 | AN6: =SUM(AN58:AN86) -> 0 | AO6: =SUM(AO58:AO86) -> 0 | AP6: =IFERROR(AJ6/AI6,"") | AQ6: =IFERROR(AK6/AJ6,"") | AR6: =IFERROR(AL6/AK6,"") | AS6: =IFERROR(AL6/AJ6,"") | AT6: =IFERROR(AN6/AL6,"") | AU6: =IFERROR(AM6/AL6,"") | AV6: =IFERROR(AI6/AL6,"") | AW6: =IFERROR(AO6/AL6,"") | AX6: =SUM(AX58:AX86) -> 0 | AY6: =SUM(AY58:AY86) -> 0 | AZ6: =SUM(AZ58:AZ86) -> 0 | BA6: =SUM(BA58:BA86) -> 0 | BB6: =IFERROR(AY6/AX6,"") | BC6: =IFERROR(AZ6/AX6,"") | BD6: =IFERROR(BA6/AX6,"")
A7: MARS | B7: =SUM(B88:B118) -> 30 | C7: =SUM(C88:C118) -> 15 | D7: =SUM(D88:D118) -> 9 | E7: =SUM(E88:E118) -> 1 | F7: =SUM(F88:F118) -> 2 | G7: =SUM(G88:G118) -> 4 | H7: =SUM(H88:H118) -> 0 | I7: =SUM(I88:I118) -> 0 | J7: =SUM(J88:J118) -> 1 | K7: =IFERROR(C7/B7,"") -> 0.5 | L7: =IFERROR(D7/(C7-E7),"") -> 0.64285714 | M7: =IFERROR(F7/(C7-E7),"") -> 0.14285714 | N7: =IFERROR(G7/(C7-E7),"") -> 0.28571429 | O7: =IFERROR((C7-E7)/C7,"") -> 0.93333333 | P7: =IFERROR(H7/D7,"") -> 0 | Q7: =IFERROR(I7/D7,"") -> 0 | R7: =IFERROR(B7/D7,"") -> 3.3333333 | S7: =IFERROR(J7/D7,"") -> 0.11111111 | T7: =SUM(T88:T118) -> 2 | U7: =SUM(U88:U118) -> 0 | V7: =SUM(V88:V118) -> 0 | W7: =SUM(W88:W118) -> 3 | X7: =SUM(X88:X118) -> 0 | Y7: =SUM(Y88:Y118) -> 0 | Z7: =SUM(Z88:Z118) -> 0 | AA7: =IFERROR(U7/T7,"") -> 0 | AB7: =IFERROR(V7/U7,"") | AC7: =IFERROR(W7/V7,"") | AD7: =IFERROR(W7/U7,"") | AE7: =IFERROR(Y7/W7,"") -> 0 | AF7: =IFERROR(X7/W7,"") -> 0 | AG7: =IFERROR(T7/W7,"") -> 0.66666667 | AH7: =IFERROR(Z7/W7,"") -> 0 | AI7: =SUM(AI88:AI118) -> 0 | AJ7: =SUM(AJ88:AJ118) -> 0 | AK7: =SUM(AK88:AK118) -> 0 | AL7: =SUM(AL88:AL118) -> 0 | AM7: =SUM(AM88:AM118) -> 0 | AN7: =SUM(AN88:AN118) -> 0 | AO7: =SUM(AO88:AO118) -> 0 | AP7: =IFERROR(AJ7/AI7,"") | AQ7: =IFERROR(AK7/AJ7,"") | AR7: =IFERROR(AL7/AK7,"") | AS7: =IFERROR(AL7/AJ7,"") | AT7: =IFERROR(AN7/AL7,"") | AU7: =IFERROR(AM7/AL7,"") | AV7: =IFERROR(AI7/AL7,"") | AW7: =IFERROR(AO7/AL7,"") | AX7: =SUM(AX88:AX118) -> 32 | AY7: =SUM(AY88:AY118) -> 0 | AZ7: =SUM(AZ88:AZ118) -> 0 | BA7: =SUM(BA88:BA118) -> 1 | BB7: =IFERROR(AY7/AX7,"") -> 0 | BC7: =IFERROR(AZ7/AX7,"") -> 0 | BD7: =IFERROR(BA7/AX7,"") -> 0.03125
A8: AVRIL | B8: =SUM(B120:B149) -> 0 | C8: =SUM(C120:C149) -> 0 | D8: =SUM(D120:D149) -> 0 | E8: =SUM(E120:E149) -> 0 | F8: =SUM(F120:F149) -> 0 | G8: =SUM(G120:G149) -> 0 | H8: =SUM(H120:H149) -> 0 | I8: =SUM(I120:I149) -> 0 | J8: =SUM(J120:J149) -> 0 | K8: =IFERROR(C8/B8,"") | L8: =IFERROR(D8/(C8-E8),"") | M8: =IFERROR(F8/(C8-E8),"") | N8: =IFERROR(G8/(C8-E8),"") | O8: =IFERROR((C8-E8)/C8,"") | P8: =IFERROR(H8/D8,"") | Q8: =IFERROR(I8/D8,"") | R8: =IFERROR(B8/D8,"") | S8: =IFERROR(J8/D8,"") | T8: =SUM(T120:T149) -> 0 | U8: =SUM(U120:U149) -> 0 | V8: =SUM(V120:V149) -> 0 | W8: =SUM(W120:W149) -> 0 | X8: =SUM(X120:X149) -> 0 | Y8: =SUM(Y120:Y149) -> 0 | Z8: =SUM(Z120:Z149) -> 0 | AA8: =IFERROR(U8/T8,"") | AB8: =IFERROR(V8/U8,"") | AC8: =IFERROR(W8/V8,"") | AD8: =IFERROR(W8/U8,"") | AE8: =IFERROR(Y8/W8,"") | AF8: =IFERROR(X8/W8,"") | AG8: =IFERROR(T8/W8,"") | AH8: =IFERROR(Z8/W8,"") | AI8: =SUM(AI120:AI149) -> 0 | AJ8: =SUM(AJ120:AJ149) -> 0 | AK8: =SUM(AK120:AK149) -> 0 | AL8: =SUM(AL120:AL149) -> 0 | AM8: =SUM(AM120:AM149) -> 0 | AN8: =SUM(AN120:AN149) -> 0 | AO8: =SUM(AO120:AO149) -> 0 | AP8: =IFERROR(AJ8/AI8,"") | AQ8: =IFERROR(AK8/AJ8,"") | AR8: =IFERROR(AL8/AK8,"") | AS8: =IFERROR(AL8/AJ8,"") | AT8: =IFERROR(AN8/AL8,"") | AU8: =IFERROR(AM8/AL8,"") | AV8: =IFERROR(AI8/AL8,"") | AW8: =IFERROR(AO8/AL8,"") | AX8: =SUM(AX120:AX149) -> 0 | AY8: =SUM(AY120:AY149) -> 0 | AZ8: =SUM(AZ120:AZ149) -> 0 | BA8: =SUM(BA120:BA149) -> 0 | BB8: =IFERROR(AY8/AX8,"") | BC8: =IFERROR(AZ8/AX8,"") | BD8: =IFERROR(BA8/AX8,"")
A9: MAI | B9: =SUM(B151:B181) -> 0 | C9: =SUM(C151:C181) -> 0 | D9: =SUM(D151:D181) -> 0 | E9: =SUM(E151:E181) -> 0 | F9: =SUM(F151:F181) -> 0 | G9: =SUM(G151:G181) -> 0 | H9: =SUM(H151:H181) -> 0 | I9: =SUM(I151:I181) -> 0 | J9: =SUM(J151:J181) -> 0 | K9: =IFERROR(C9/B9,"") | L9: =IFERROR(D9/(C9-E9),"") | M9: =IFERROR(F9/(C9-E9),"") | N9: =IFERROR(G9/(C9-E9),"") | O9: =IFERROR((C9-E9)/C9,"") | P9: =IFERROR(H9/D9,"") | Q9: =IFERROR(I9/D9,"") | R9: =IFERROR(B9/D9,"") | S9: =IFERROR(J9/D9,"") | T9: =SUM(T151:T181) -> 0 | U9: =SUM(U151:U181) -> 0 | V9: =SUM(V151:V181) -> 0 | W9: =SUM(W151:W181) -> 0 | X9: =SUM(X151:X181) -> 0 | Y9: =SUM(Y151:Y181) -> 0 | Z9: =SUM(Z151:Z181) -> 0 | AA9: =IFERROR(U9/T9,"") | AB9: =IFERROR(V9/U9,"") | AC9: =IFERROR(W9/V9,"") | AD9: =IFERROR(W9/U9,"") | AE9: =IFERROR(Y9/W9,"") | AF9: =IFERROR(X9/W9,"") | AG9: =IFERROR(T9/W9,"") | AH9: =IFERROR(Z9/W9,"") | AI9: =SUM(AI151:AI181) -> 0 | AJ9: =SUM(AJ151:AJ181) -> 0 | AK9: =SUM(AK151:AK181) -> 0 | AL9: =SUM(AL151:AL181) -> 0 | AM9: =SUM(AM151:AM181) -> 0 | AN9: =SUM(AN151:AN181) -> 0 | AO9: =SUM(AO151:AO181) -> 0 | AP9: =IFERROR(AJ9/AI9,"") | AQ9: =IFERROR(AK9/AJ9,"") | AR9: =IFERROR(AL9/AK9,"") | AS9: =IFERROR(AL9/AJ9,"") | AT9: =IFERROR(AN9/AL9,"") | AU9: =IFERROR(AM9/AL9,"") | AV9: =IFERROR(AI9/AL9,"") | AW9: =IFERROR(AO9/AL9,"") | AX9: =SUM(AX151:AX181) -> 0 | AY9: =SUM(AY151:AY181) -> 0 | AZ9: =SUM(AZ151:AZ181) -> 0 | BA9: =SUM(BA151:BA181) -> 0 | BB9: =IFERROR(AY9/AX9,"") | BC9: =IFERROR(AZ9/AX9,"") | BD9: =IFERROR(BA9/AX9,"")
A10: JUIN | B10: =SUM(B183:B212) -> 0 | C10: =SUM(C183:C212) -> 0 | D10: =SUM(D183:D212) -> 0 | E10: =SUM(E183:E212) -> 0 | F10: =SUM(F183:F212) -> 0 | G10: =SUM(G183:G212) -> 0 | H10: =SUM(H183:H212) -> 0 | I10: =SUM(I183:I212) -> 0 | J10: =SUM(J183:J212) -> 0 | K10: =IFERROR(C10/B10,"") | L10: =IFERROR(D10/(C10-E10),"") | M10: =IFERROR(F10/(C10-E10),"") | N10: =IFERROR(G10/(C10-E10),"") | O10: =IFERROR((C10-E10)/C10,"") | P10: =IFERROR(H10/D10,"") | Q10: =IFERROR(I10/D10,"") | R10: =IFERROR(B10/D10,"") | S10: =IFERROR(J10/D10,"") | T10: =SUM(T183:T212) -> 0 | U10: =SUM(U183:U212) -> 0 | V10: =SUM(V183:V212) -> 0 | W10: =SUM(W183:W212) -> 0 | X10: =SUM(X183:X212) -> 0 | Y10: =SUM(Y183:Y212) -> 0 | Z10: =SUM(Z183:Z212) -> 0 | AA10: =IFERROR(U10/T10,"") | AB10: =IFERROR(V10/U10,"") | AC10: =IFERROR(W10/V10,"") | AD10: =IFERROR(W10/U10,"") | AE10: =IFERROR(Y10/W10,"") | AF10: =IFERROR(X10/W10,"") | AG10: =IFERROR(T10/W10,"") | AH10: =IFERROR(Z10/W10,"") | AI10: =SUM(AI183:AI212) -> 0 | AJ10: =SUM(AJ183:AJ212) -> 0 | AK10: =SUM(AK183:AK212) -> 0 | AL10: =SUM(AL183:AL212) -> 0 | AM10: =SUM(AM183:AM212) -> 0 | AN10: =SUM(AN183:AN212) -> 0 | AO10: =SUM(AO183:AO212) -> 0 | AP10: =IFERROR(AJ10/AI10,"") | AQ10: =IFERROR(AK10/AJ10,"") | AR10: =IFERROR(AL10/AK10,"") | AS10: =IFERROR(AL10/AJ10,"") | AT10: =IFERROR(AN10/AL10,"") | AU10: =IFERROR(AM10/AL10,"") | AV10: =IFERROR(AI10/AL10,"") | AW10: =IFERROR(AO10/AL10,"") | AX10: =SUM(AX183:AX212) -> 0 | AY10: =SUM(AY183:AY212) -> 0 | AZ10: =SUM(AZ183:AZ212) -> 0 | BA10: =SUM(BA183:BA212) -> 0 | BB10: =IFERROR(AY10/AX10,"") | BC10: =IFERROR(AZ10/AX10,"") | BD10: =IFERROR(BA10/AX10,"")
A11: JUILLET | B11: =SUM(B214:B244) -> 0 | C11: =SUM(C214:C244) -> 0 | D11: =SUM(D214:D244) -> 0 | E11: =SUM(E214:E244) -> 0 | F11: =SUM(F214:F244) -> 0 | G11: =SUM(G214:G244) -> 0 | H11: =SUM(H214:H244) -> 0 | I11: =SUM(I214:I244) -> 0 | J11: =SUM(J214:J244) -> 0 | K11: =IFERROR(C11/B11,"") | L11: =IFERROR(D11/(C11-E11),"") | M11: =IFERROR(F11/(C11-E11),"") | N11: =IFERROR(G11/(C11-E11),"") | O11: =IFERROR((C11-E11)/C11,"") | P11: =IFERROR(H11/D11,"") | Q11: =IFERROR(I11/D11,"") | R11: =IFERROR(B11/D11,"") | S11: =IFERROR(J11/D11,"") | T11: =SUM(T214:T244) -> 0 | U11: =SUM(U214:U244) -> 0 | V11: =SUM(V214:V244) -> 0 | W11: =SUM(W214:W244) -> 0 | X11: =SUM(X214:X244) -> 0 | Y11: =SUM(Y214:Y244) -> 0 | Z11: =SUM(Z214:Z244) -> 0 | AA11: =IFERROR(U11/T11,"") | AB11: =IFERROR(V11/U11,"") | AC11: =IFERROR(W11/V11,"") | AD11: =IFERROR(W11/U11,"") | AE11: =IFERROR(Y11/W11,"") | AF11: =IFERROR(X11/W11,"") | AG11: =IFERROR(T11/W11,"") | AH11: =IFERROR(Z11/W11,"") | AI11: =SUM(AI214:AI244) -> 0 | AJ11: =SUM(AJ214:AJ244) -> 0 | AK11: =SUM(AK214:AK244) -> 0 | AL11: =SUM(AL214:AL244) -> 0 | AM11: =SUM(AM214:AM244) -> 0 | AN11: =SUM(AN214:AN244) -> 0 | AO11: =SUM(AO214:AO244) -> 0 | AP11: =IFERROR(AJ11/AI11,"") | AQ11: =IFERROR(AK11/AJ11,"") | AR11: =IFERROR(AL11/AK11,"") | AS11: =IFERROR(AL11/AJ11,"") | AT11: =IFERROR(AN11/AL11,"") | AU11: =IFERROR(AM11/AL11,"") | AV11: =IFERROR(AI11/AL11,"") | AW11: =IFERROR(AO11/AL11,"") | AX11: =SUM(AX214:AX244) -> 0 | AY11: =SUM(AY214:AY244) -> 0 | AZ11: =SUM(AZ214:AZ244) -> 0 | BA11: =SUM(BA214:BA244) -> 0 | BB11: =IFERROR(AY11/AX11,"") | BC11: =IFERROR(AZ11/AX11,"") | BD11: =IFERROR(BA11/AX11,"")
A12: AOÛT | B12: =SUM(B246:B276) -> 0 | C12: =SUM(C246:C276) -> 0 | D12: =SUM(D246:D276) -> 0 | E12: =SUM(E246:E276) -> 0 | F12: =SUM(F246:F276) -> 0 | G12: =SUM(G246:G276) -> 0 | H12: =SUM(H246:H276) -> 0 | I12: =SUM(I246:I276) -> 0 | J12: =SUM(J246:J276) -> 0 | K12: =IFERROR(C12/B12,"") | L12: =IFERROR(D12/(C12-E12),"") | M12: =IFERROR(F12/(C12-E12),"") | N12: =IFERROR(G12/(C12-E12),"") | O12: =IFERROR((C12-E12)/C12,"") | P12: =IFERROR(H12/D12,"") | Q12: =IFERROR(I12/D12,"") | R12: =IFERROR(B12/D12,"") | S12: =IFERROR(J12/D12,"") | T12: =SUM(T246:T276) -> 0 | U12: =SUM(U246:U276) -> 0 | V12: =SUM(V246:V276) -> 0 | W12: =SUM(W246:W276) -> 0 | X12: =SUM(X246:X276) -> 0 | Y12: =SUM(Y246:Y276) -> 0 | Z12: =SUM(Z246:Z276) -> 0 | AA12: =IFERROR(U12/T12,"") | AB12: =IFERROR(V12/U12,"") | AC12: =IFERROR(W12/V12,"") | AD12: =IFERROR(W12/U12,"") | AE12: =IFERROR(Y12/W12,"") | AF12: =IFERROR(X12/W12,"") | AG12: =IFERROR(T12/W12,"") | AH12: =IFERROR(Z12/W12,"") | AI12: =SUM(AI246:AI276) -> 0 | AJ12: =SUM(AJ246:AJ276) -> 0 | AK12: =SUM(AK246:AK276) -> 0 | AL12: =SUM(AL246:AL276) -> 0 | AM12: =SUM(AM246:AM276) -> 0 | AN12: =SUM(AN246:AN276) -> 0 | AO12: =SUM(AO246:AO276) -> 0 | AP12: =IFERROR(AJ12/AI12,"") | AQ12: =IFERROR(AK12/AJ12,"") | AR12: =IFERROR(AL12/AK12,"") | AS12: =IFERROR(AL12/AJ12,"") | AT12: =IFERROR(AN12/AL12,"") | AU12: =IFERROR(AM12/AL12,"") | AV12: =IFERROR(AI12/AL12,"") | AW12: =IFERROR(AO12/AL12,"") | AX12: =SUM(AX246:AX276) -> 0 | AY12: =SUM(AY246:AY276) -> 0 | AZ12: =SUM(AZ246:AZ276) -> 0 | BA12: =SUM(BA246:BA276) -> 0 | BB12: =IFERROR(AY12/AX12,"") | BC12: =IFERROR(AZ12/AX12,"") | BD12: =IFERROR(BA12/AX12,"")
A13: SEPTEMBRE | B13: =SUM(B278:B307) -> 0 | C13: =SUM(C278:C307) -> 0 | D13: =SUM(D278:D307) -> 0 | E13: =SUM(E278:E307) -> 0 | F13: =SUM(F278:F307) -> 0 | G13: =SUM(G278:G307) -> 0 | H13: =SUM(H278:H307) -> 0 | I13: =SUM(I278:I307) -> 0 | J13: =SUM(J278:J307) -> 0 | K13: =IFERROR(C13/B13,"") | L13: =IFERROR(D13/(C13-E13),"") | M13: =IFERROR(F13/(C13-E13),"") | N13: =IFERROR(G13/(C13-E13),"") | O13: =IFERROR((C13-E13)/C13,"") | P13: =IFERROR(H13/D13,"") | Q13: =IFERROR(I13/D13,"") | R13: =IFERROR(B13/D13,"") | S13: =IFERROR(J13/D13,"") | T13: =SUM(T278:T307) -> 0 | U13: =SUM(U278:U307) -> 0 | V13: =SUM(V278:V307) -> 0 | W13: =SUM(W278:W307) -> 0 | X13: =SUM(X278:X307) -> 0 | Y13: =SUM(Y278:Y307) -> 0 | Z13: =SUM(Z278:Z307) -> 0 | AA13: =IFERROR(U13/T13,"") | AB13: =IFERROR(V13/U13,"") | AC13: =IFERROR(W13/V13,"") | AD13: =IFERROR(W13/U13,"") | AE13: =IFERROR(Y13/W13,"") | AF13: =IFERROR(X13/W13,"") | AG13: =IFERROR(T13/W13,"") | AH13: =IFERROR(Z13/W13,"") | AI13: =SUM(AI278:AI307) -> 0 | AJ13: =SUM(AJ278:AJ307) -> 0 | AK13: =SUM(AK278:AK307) -> 0 | AL13: =SUM(AL278:AL307) -> 0 | AM13: =SUM(AM278:AM307) -> 0 | AN13: =SUM(AN278:AN307) -> 0 | AO13: =SUM(AO278:AO307) -> 0 | AP13: =IFERROR(AJ13/AI13,"") | AQ13: =IFERROR(AK13/AJ13,"") | AR13: =IFERROR(AL13/AK13,"") | AS13: =IFERROR(AL13/AJ13,"") | AT13: =IFERROR(AN13/AL13,"") | AU13: =IFERROR(AM13/AL13,"") | AV13: =IFERROR(AI13/AL13,"") | AW13: =IFERROR(AO13/AL13,"") | AX13: =SUM(AX278:AX307) -> 0 | AY13: =SUM(AY278:AY307) -> 0 | AZ13: =SUM(AZ278:AZ307) -> 0 | BA13: =SUM(BA278:BA307) -> 0 | BB13: =IFERROR(AY13/AX13,"") | BC13: =IFERROR(AZ13/AX13,"") | BD13: =IFERROR(BA13/AX13,"")
A14: OCTOBRE | B14: =SUM(B309:B339) -> 0 | C14: =SUM(C309:C339) -> 0 | D14: =SUM(D309:D339) -> 0 | E14: =SUM(E309:E339) -> 0 | F14: =SUM(F309:F339) -> 0 | G14: =SUM(G309:G339) -> 0 | H14: =SUM(H309:H339) -> 0 | I14: =SUM(I309:I339) -> 0 | J14: =SUM(J309:J339) -> 0 | K14: =IFERROR(C14/B14,"") | L14: =IFERROR(D14/(C14-E14),"") | M14: =IFERROR(F14/(C14-E14),"") | N14: =IFERROR(G14/(C14-E14),"") | O14: =IFERROR((C14-E14)/C14,"") | P14: =IFERROR(H14/D14,"") | Q14: =IFERROR(I14/D14,"") | R14: =IFERROR(B14/D14,"") | S14: =IFERROR(J14/D14,"") | T14: =SUM(T309:T339) -> 0 | U14: =SUM(U309:U339) -> 0 | V14: =SUM(V309:V339) -> 0 | W14: =SUM(W309:W339) -> 0 | X14: =SUM(X309:X339) -> 0 | Y14: =SUM(Y309:Y339) -> 0 | Z14: =SUM(Z309:Z339) -> 0 | AA14: =IFERROR(U14/T14,"") | AB14: =IFERROR(V14/U14,"") | AC14: =IFERROR(W14/V14,"") | AD14: =IFERROR(W14/U14,"") | AE14: =IFERROR(Y14/W14,"") | AF14: =IFERROR(X14/W14,"") | AG14: =IFERROR(T14/W14,"") | AH14: =IFERROR(Z14/W14,"") | AI14: =SUM(AI309:AI339) -> 0 | AJ14: =SUM(AJ309:AJ339) -> 0 | AK14: =SUM(AK309:AK339) -> 0 | AL14: =SUM(AL309:AL339) -> 0 | AM14: =SUM(AM309:AM339) -> 0 | AN14: =SUM(AN309:AN339) -> 0 | AO14: =SUM(AO309:AO339) -> 0 | AP14: =IFERROR(AJ14/AI14,"") | AQ14: =IFERROR(AK14/AJ14,"") | AR14: =IFERROR(AL14/AK14,"") | AS14: =IFERROR(AL14/AJ14,"") | AT14: =IFERROR(AN14/AL14,"") | AU14: =IFERROR(AM14/AL14,"") | AV14: =IFERROR(AI14/AL14,"") | AW14: =IFERROR(AO14/AL14,"") | AX14: =SUM(AX309:AX339) -> 0 | AY14: =SUM(AY309:AY339) -> 0 | AZ14: =SUM(AZ309:AZ339) -> 0 | BA14: =SUM(BA309:BA339) -> 0 | BB14: =IFERROR(AY14/AX14,"") | BC14: =IFERROR(AZ14/AX14,"") | BD14: =IFERROR(BA14/AX14,"")
A15: NOVEMBRE | B15: =SUM(B341:B370) -> 0 | C15: =SUM(C341:C370) -> 0 | D15: =SUM(D341:D370) -> 0 | E15: =SUM(E341:E370) -> 0 | F15: =SUM(F341:F370) -> 0 | G15: =SUM(G341:G370) -> 0 | H15: =SUM(H341:H370) -> 0 | I15: =SUM(I341:I370) -> 0 | J15: =SUM(J341:J370) -> 0 | K15: =IFERROR(C15/B15,"") | L15: =IFERROR(D15/(C15-E15),"") | M15: =IFERROR(F15/(C15-E15),"") | N15: =IFERROR(G15/(C15-E15),"") | O15: =IFERROR((C15-E15)/C15,"") | P15: =IFERROR(H15/D15,"") | Q15: =IFERROR(I15/D15,"") | R15: =IFERROR(B15/D15,"") | S15: =IFERROR(J15/D15,"") | T15: =SUM(T341:T370) -> 0 | U15: =SUM(U341:U370) -> 0 | V15: =SUM(V341:V370) -> 0 | W15: =SUM(W341:W370) -> 0 | X15: =SUM(X341:X370) -> 0 | Y15: =SUM(Y341:Y370) -> 0 | Z15: =SUM(Z341:Z370) -> 0 | AA15: =IFERROR(U15/T15,"") | AB15: =IFERROR(V15/U15,"") | AC15: =IFERROR(W15/V15,"") | AD15: =IFERROR(W15/U15,"") | AE15: =IFERROR(Y15/W15,"") | AF15: =IFERROR(X15/W15,"") | AG15: =IFERROR(T15/W15,"") | AH15: =IFERROR(Z15/W15,"") | AI15: =SUM(AI341:AI370) -> 0 | AJ15: =SUM(AJ341:AJ370) -> 0 | AK15: =SUM(AK341:AK370) -> 0 | AL15: =SUM(AL341:AL370) -> 0 | AM15: =SUM(AM341:AM370) -> 0 | AN15: =SUM(AN341:AN370) -> 0 | AO15: =SUM(AO341:AO370) -> 0 | AP15: =IFERROR(AJ15/AI15,"") | AQ15: =IFERROR(AK15/AJ15,"") | AR15: =IFERROR(AL15/AK15,"") | AS15: =IFERROR(AL15/AJ15,"") | AT15: =IFERROR(AN15/AL15,"") | AU15: =IFERROR(AM15/AL15,"") | AV15: =IFERROR(AI15/AL15,"") | AW15: =IFERROR(AO15/AL15,"") | AX15: =SUM(AX341:AX370) -> 0 | AY15: =SUM(AY341:AY370) -> 0 | AZ15: =SUM(AZ341:AZ370) -> 0 | BA15: =SUM(BA341:BA370) -> 0 | BB15: =IFERROR(AY15/AX15,"") | BC15: =IFERROR(AZ15/AX15,"") | BD15: =IFERROR(BA15/AX15,"")
A16: DÉCEMBRE | B16: =SUM(B372:B402) -> 0 | C16: =SUM(C372:C402) -> 0 | D16: =SUM(D372:D402) -> 0 | E16: =SUM(E372:E402) -> 0 | F16: =SUM(F372:F402) -> 0 | G16: =SUM(G372:G402) -> 0 | H16: =SUM(H372:H402) -> 0 | I16: =SUM(I372:I402) -> 0 | J16: =SUM(J372:J402) -> 0 | K16: =IFERROR(C16/B16,"") | L16: =IFERROR(D16/(C16-E16),"") | M16: =IFERROR(F16/(C16-E16),"") | N16: =IFERROR(G16/(C16-E16),"") | O16: =IFERROR((C16-E16)/C16,"") | P16: =IFERROR(H16/D16,"") | Q16: =IFERROR(I16/D16,"") | R16: =IFERROR(B16/D16,"") | S16: =IFERROR(J16/D16,"") | T16: =SUM(T372:T402) -> 0 | U16: =SUM(U372:U402) -> 0 | V16: =SUM(V372:V402) -> 0 | W16: =SUM(W372:W402) -> 0 | X16: =SUM(X372:X402) -> 0 | Y16: =SUM(Y372:Y402) -> 0 | Z16: =SUM(Z372:Z402) -> 0 | AA16: =IFERROR(U16/T16,"") | AB16: =IFERROR(V16/U16,"") | AC16: =IFERROR(W16/V16,"") | AD16: =IFERROR(W16/U16,"") | AE16: =IFERROR(Y16/W16,"") | AF16: =IFERROR(X16/W16,"") | AG16: =IFERROR(T16/W16,"") | AH16: =IFERROR(Z16/W16,"") | AI16: =SUM(AI372:AI402) -> 0 | AJ16: =SUM(AJ372:AJ402) -> 0 | AK16: =SUM(AK372:AK402) -> 0 | AL16: =SUM(AL372:AL402) -> 0 | AM16: =SUM(AM372:AM402) -> 0 | AN16: =SUM(AN372:AN402) -> 0 | AO16: =SUM(AO372:AO402) -> 0 | AP16: =IFERROR(AJ16/AI16,"") | AQ16: =IFERROR(AK16/AJ16,"") | AR16: =IFERROR(AL16/AK16,"") | AS16: =IFERROR(AL16/AJ16,"") | AT16: =IFERROR(AN16/AL16,"") | AU16: =IFERROR(AM16/AL16,"") | AV16: =IFERROR(AI16/AL16,"") | AW16: =IFERROR(AO16/AL16,"") | AX16: =SUM(AX372:AX402) -> 0 | AY16: =SUM(AY372:AY402) -> 0 | AZ16: =SUM(AZ372:AZ402) -> 0 | BA16: =SUM(BA372:BA402) -> 0 | BB16: =IFERROR(AY16/AX16,"") | BC16: =IFERROR(AZ16/AX16,"") | BD16: =IFERROR(BA16/AX16,"")
K17: =IFERROR(C17/B17,"") | L17: =IFERROR(D17/(C17-E17),"") | M17: =IFERROR(#REF!/D17,"") | N17: =IFERROR(#REF!/D17,"") | S17: =IFERROR(D17/B17,"") | AA17: =IFERROR(V17/T17,"") | AB17: =IFERROR(W17/(V17-X17),"") | AC17: =IFERROR(#REF!/W17,"") | AD17: =IFERROR(#REF!/W17,"") | AG17: =IFERROR(W17/T17,"") | AP17: =IFERROR(AK17/AI17,"") | AQ17: =IFERROR(AL17/(AK17-AM17),"") | AR17: =IFERROR(#REF!/AL17,"") | AS17: =IFERROR(#REF!/AL17,"") | AV17: =IFERROR(AL17/AI17,"") | BB17: =IFERROR(AY17/AX17,"") | BC17: =IFERROR(AZ17/(AY17-BA17),"") | BD17: =IFERROR(#REF!/AZ17,"")
A18: TRIMESTRE | K18: =IFERROR(#REF!/#REF!,"") | AA18: =IFERROR(#REF!/#REF!,"") | AP18: =IFERROR(#REF!/#REF!,"") | BB18: =IFERROR(#REF!/#REF!,"")
A19: 1 | B19: =SUM(B5,B6,B7) -> 30 | C19: =SUM(C5,C6,C7) -> 15 | D19: =SUM(D5,D6,D7) -> 9 | E19: =SUM(E5,E6,E7) -> 1 | F19: =SUM(F5,F6,F7) -> 2 | G19: =SUM(G5,G6,G7) -> 4 | H19: =SUM(H5,H6,H7) -> 0 | I19: =SUM(I5,I6,I7) -> 0 | J19: =SUM(J5,J6,J7) -> 1 | K19: =IFERROR(C19/B19,"") -> 0.5 | L19: =IFERROR(D19/(C19-E19),"") -> 0.64285714 | M19: =IFERROR(F19/(C19-E19),"") -> 0.14285714 | N19: =IFERROR(G19/(C19-E19),"") -> 0.28571429 | O19: =IFERROR((C19-E19)/C19,"") -> 0.93333333 | P19: =IFERROR(H19/D19,"") -> 0 | Q19: =IFERROR(I19/D19,"") -> 0 | R19: =IFERROR(B19/D19,"") -> 3.3333333 | S19: =IFERROR(J19/D19,"") -> 0.11111111 | T19: =SUM(T5,T6,T7) -> 2 | U19: =SUM(U5,U6,U7) -> 0 | V19: =SUM(V5,V6,V7) -> 0 | W19: =SUM(W5,W6,W7) -> 3 | X19: =SUM(X5,X6,X7) -> 0 | Y19: =SUM(Y5,Y6,Y7) -> 0 | Z19: =SUM(Z5,Z6,Z7) -> 0 | AA19: =IFERROR(U19/T19,"") -> 0 | AB19: =IFERROR(V19/U19,"") | AC19: =IFERROR(W19/V19,"") | AD19: =IFERROR(W19/U19,"") | AE19: =IFERROR(Y19/W19,"") -> 0 | AF19: =IFERROR(X19/W19,"") -> 0 | AG19: =IFERROR(T19/W19,"") -> 0.66666667 | AH19: =IFERROR(Z19/W19,"") -> 0 | AI19: =SUM(AI5,AI6,AI7) -> 0 | AJ19: =SUM(AJ5,AJ6,AJ7) -> 0 | AK19: =SUM(AK5,AK6,AK7) -> 0 | AL19: =SUM(AL5,AL6,AL7) -> 0 | AM19: =SUM(AM5,AM6,AM7) -> 0 | AN19: =SUM(AN5,AN6,AN7) -> 0 | AO19: =SUM(AO5,AO6,AO7) -> 0 | AP19: =IFERROR(AJ19/AI19,"") | AQ19: =IFERROR(AK19/AJ19,"") | AR19: =IFERROR(AL19/AK19,"") | AS19: =IFERROR(AL19/AJ19,"") | AT19: =IFERROR(AN19/AL19,"") | AU19: =IFERROR(AM19/AL19,"") | AV19: =IFERROR(AI19/AL19,"") | AW19: =IFERROR(AO19/AL19,"") | AX19: =SUM(AX5,AX6,AX7) -> 32 | AY19: =SUM(AY5,AY6,AY7) -> 0 | AZ19: =SUM(AZ5,AZ6,AZ7) -> 0 | BA19: =SUM(BA5,BA6,BA7) -> 1 | BB19: =IFERROR(AY19/AX19,"") -> 0 | BC19: =IFERROR(AZ19/AX19,"") -> 0 | BD19: =IFERROR(BA19/AX19,"") -> 0.03125
A20: 2 | B20: =SUM(B8,B9,B10) -> 0 | C20: =SUM(C8,C9,C10) -> 0 | D20: =SUM(D8,D9,D10) -> 0 | E20: =SUM(E8,E9,E10) -> 0 | F20: =SUM(F8,F9,F10) -> 0 | G20: =SUM(G8,G9,G10) -> 0 | H20: =SUM(H8,H9,H10) -> 0 | I20: =SUM(I8,I9,I10) -> 0 | J20: =SUM(J8,J9,J10) -> 0 | K20: =IFERROR(C20/B20,"") | L20: =IFERROR(D20/(C20-E20),"") | M20: =IFERROR(F20/(C20-E20),"") | N20: =IFERROR(G20/(C20-E20),"") | O20: =IFERROR((C20-E20)/C20,"") | P20: =IFERROR(H20/D20,"") | Q20: =IFERROR(I20/D20,"") | R20: =IFERROR(B20/D20,"") | S20: =IFERROR(J20/D20,"") | T20: =SUM(T8,T9,T10) -> 0 | U20: =SUM(U8,U9,U10) -> 0 | V20: =SUM(V8,V9,V10) -> 0 | W20: =SUM(W8,W9,W10) -> 0 | X20: =SUM(X8,X9,X10) -> 0 | Y20: =SUM(Y8,Y9,Y10) -> 0 | Z20: =SUM(Z8,Z9,Z10) -> 0 | AA20: =IFERROR(U20/T20,"") | AB20: =IFERROR(V20/U20,"") | AC20: =IFERROR(W20/V20,"") | AD20: =IFERROR(W20/U20,"") | AE20: =IFERROR(Y20/W20,"") | AF20: =IFERROR(X20/W20,"") | AG20: =IFERROR(T20/W20,"") | AH20: =IFERROR(Z20/W20,"") | AI20: =SUM(AI8,AI9,AI10) -> 0 | AJ20: =SUM(AJ8,AJ9,AJ10) -> 0 | AK20: =SUM(AK8,AK9,AK10) -> 0 | AL20: =SUM(AL8,AL9,AL10) -> 0 | AM20: =SUM(AM8,AM9,AM10) -> 0 | AN20: =SUM(AN8,AN9,AN10) -> 0 | AO20: =SUM(AO8,AO9,AO10) -> 0 | AP20: =IFERROR(AJ20/AI20,"") | AQ20: =IFERROR(AK20/AJ20,"") | AR20: =IFERROR(AL20/AK20,"") | AS20: =IFERROR(AL20/AJ20,"") | AT20: =IFERROR(AN20/AL20,"") | AU20: =IFERROR(AM20/AL20,"") | AV20: =IFERROR(AI20/AL20,"") | AW20: =IFERROR(AO20/AL20,"") | AX20: =SUM(AX8,AX9,AX10) -> 0 | AY20: =SUM(AY8,AY9,AY10) -> 0 | AZ20: =SUM(AZ8,AZ9,AZ10) -> 0 | BA20: =SUM(BA8,BA9,BA10) -> 0 | BB20: =IFERROR(AY20/AX20,"") | BC20: =IFERROR(AZ20/AX20,"") | BD20: =IFERROR(BA20/AX20,"")
A21: 3 | B21: =SUM(B11,B12,B13) -> 0 | C21: =SUM(C11,C12,C13) -> 0 | D21: =SUM(D11,D12,D13) -> 0 | E21: =SUM(E11,E12,E13) -> 0 | F21: =SUM(F11,F12,F13) -> 0 | G21: =SUM(G11,G12,G13) -> 0 | H21: =SUM(H11,H12,H13) -> 0 | I21: =SUM(I11,I12,I13) -> 0 | J21: =SUM(J11,J12,J13) -> 0 | K21: =IFERROR(C21/B21,"") | L21: =IFERROR(D21/(C21-E21),"") | M21: =IFERROR(F21/(C21-E21),"") | N21: =IFERROR(G21/(C21-E21),"") | O21: =IFERROR((C21-E21)/C21,"") | P21: =IFERROR(H21/D21,"") | Q21: =IFERROR(I21/D21,"") | R21: =IFERROR(B21/D21,"") | S21: =IFERROR(J21/D21,"") | T21: =SUM(T11,T12,T13) -> 0 | U21: =SUM(U11,U12,U13) -> 0 | V21: =SUM(V11,V12,V13) -> 0 | W21: =SUM(W11,W12,W13) -> 0 | X21: =SUM(X11,X12,X13) -> 0 | Y21: =SUM(Y11,Y12,Y13) -> 0 | Z21: =SUM(Z11,Z12,Z13) -> 0 | AA21: =IFERROR(U21/T21,"") | AB21: =IFERROR(V21/U21,"") | AC21: =IFERROR(W21/V21,"") | AD21: =IFERROR(W21/U21,"") | AE21: =IFERROR(Y21/W21,"") | AF21: =IFERROR(X21/W21,"") | AG21: =IFERROR(T21/W21,"") | AH21: =IFERROR(Z21/W21,"") | AI21: =SUM(AI11,AI12,AI13) -> 0 | AJ21: =SUM(AJ11,AJ12,AJ13) -> 0 | AK21: =SUM(AK11,AK12,AK13) -> 0 | AL21: =SUM(AL11,AL12,AL13) -> 0 | AM21: =SUM(AM11,AM12,AM13) -> 0 | AN21: =SUM(AN11,AN12,AN13) -> 0 | AO21: =SUM(AO11,AO12,AO13) -> 0 | AP21: =IFERROR(AJ21/AI21,"") | AQ21: =IFERROR(AK21/AJ21,"") | AR21: =IFERROR(AL21/AK21,"") | AS21: =IFERROR(AL21/AJ21,"") | AT21: =IFERROR(AN21/AL21,"") | AU21: =IFERROR(AM21/AL21,"") | AV21: =IFERROR(AI21/AL21,"") | AW21: =IFERROR(AO21/AL21,"") | AX21: =SUM(AX11,AX12,AX13) -> 0 | AY21: =SUM(AY11,AY12,AY13) -> 0 | AZ21: =SUM(AZ11,AZ12,AZ13) -> 0 | BA21: =SUM(BA11,BA12,BA13) -> 0 | BB21: =IFERROR(AY21/AX21,"") | BC21: =IFERROR(AZ21/AX21,"") | BD21: =IFERROR(BA21/AX21,"")
A22: 4 | B22: =SUM(B14,B15,B16) -> 0 | C22: =SUM(C14,C15,C16) -> 0 | D22: =SUM(D14,D15,D16) -> 0 | E22: =SUM(E14,E15,E16) -> 0 | F22: =SUM(F14,F15,F16) -> 0 | G22: =SUM(G14,G15,G16) -> 0 | H22: =SUM(H14,H15,H16) -> 0 | I22: =SUM(I14,I15,I16) -> 0 | J22: =SUM(J14,J15,J16) -> 0 | K22: =IFERROR(C22/B22,"") | L22: =IFERROR(D22/(C22-E22),"") | M22: =IFERROR(F22/(C22-E22),"") | N22: =IFERROR(G22/(C22-E22),"") | O22: =IFERROR((C22-E22)/C22,"") | P22: =IFERROR(H22/D22,"") | Q22: =IFERROR(I22/D22,"") | R22: =IFERROR(B22/D22,"") | S22: =IFERROR(J22/D22,"") | T22: =SUM(T14,T15,T16) -> 0 | U22: =SUM(U14,U15,U16) -> 0 | V22: =SUM(V14,V15,V16) -> 0 | W22: =SUM(W14,W15,W16) -> 0 | X22: =SUM(X14,X15,X16) -> 0 | Y22: =SUM(Y14,Y15,Y16) -> 0 | Z22: =SUM(Z14,Z15,Z16) -> 0 | AA22: =IFERROR(U22/T22,"") | AB22: =IFERROR(V22/U22,"") | AC22: =IFERROR(W22/V22,"") | AD22: =IFERROR(W22/U22,"") | AE22: =IFERROR(Y22/W22,"") | AF22: =IFERROR(X22/W22,"") | AG22: =IFERROR(T22/W22,"") | AH22: =IFERROR(Z22/W22,"") | AI22: =SUM(AI14,AI15,AI16) -> 0 | AJ22: =SUM(AJ14,AJ15,AJ16) -> 0 | AK22: =SUM(AK14,AK15,AK16) -> 0 | AL22: =SUM(AL14,AL15,AL16) -> 0 | AM22: =SUM(AM14,AM15,AM16) -> 0 | AN22: =SUM(AN14,AN15,AN16) -> 0 | AO22: =SUM(AO14,AO15,AO16) -> 0 | AP22: =IFERROR(AJ22/AI22,"") | AQ22: =IFERROR(AK22/AJ22,"") | AR22: =IFERROR(AL22/AK22,"") | AS22: =IFERROR(AL22/AJ22,"") | AT22: =IFERROR(AN22/AL22,"") | AU22: =IFERROR(AM22/AL22,"") | AV22: =IFERROR(AI22/AL22,"") | AW22: =IFERROR(AO22/AL22,"") | AX22: =SUM(AX14,AX15,AX16) -> 0 | AY22: =SUM(AY14,AY15,AY16) -> 0 | AZ22: =SUM(AZ14,AZ15,AZ16) -> 0 | BA22: =SUM(BA14,BA15,BA16) -> 0 | BB22: =IFERROR(AY22/AX22,"") | BC22: =IFERROR(AZ22/AX22,"") | BD22: =IFERROR(BA22/AX22,"")
A23: ANNÉE | K23: =IFERROR(#REF!/#REF!,"") | AA23: =IFERROR(#REF!/#REF!,"") | AP23: =IFERROR(#REF!/#REF!,"") | BB23: =IFERROR(#REF!/#REF!,"")
A24: 2025 | B24: =SUM(B19,B20,B21,B22) -> 30 | C24: =SUM(C19,C20,C21,C22) -> 15 | D24: =SUM(D19,D20,D21,D22) -> 9 | E24: =SUM(E19,E20,E21,E22) -> 1 | F24: =SUM(F19,F20,F21,F22) -> 2 | G24: =SUM(G19,G20,G21,G22) -> 4 | H24: =SUM(H19,H20,H21,H22) -> 0 | I24: =SUM(I19,I20,I21,I22) -> 0 | J24: =SUM(J19,J20,J21,J22) -> 1 | K24: =IFERROR(C24/B24,"") -> 0.5 | L24: =IFERROR(D24/(C24-E24),"") -> 0.64285714 | M24: =IFERROR(F24/(C24-E24),"") -> 0.14285714 | N24: =IFERROR(G24/(C24-E24),"") -> 0.28571429 | O24: =IFERROR((C24-E24)/C24,"") -> 0.93333333 | P24: =IFERROR(H24/D24,"") -> 0 | Q24: =IFERROR(I24/D24,"") -> 0 | R24: =IFERROR(B24/D24,"") -> 3.3333333 | S24: =IFERROR(J24/D24,"") -> 0.11111111 | T24: =SUM(T19,T20,T21,T22) -> 2 | U24: =SUM(U19,U20,U21,U22) -> 0 | V24: =SUM(V19,V20,V21,V22) -> 0 | W24: =SUM(W19,W20,W21,W22) -> 3 | X24: =SUM(X19,X20,X21,X22) -> 0 | Y24: =SUM(Y19,Y20,Y21,Y22) -> 0 | Z24: =SUM(Z19,Z20,Z21,Z22) -> 0 | AA24: =IFERROR(U24/T24,"") -> 0 | AB24: =IFERROR(V24/U24,"") | AC24: =IFERROR(W24/V24,"") | AD24: =IFERROR(W24/U24,"") | AE24: =IFERROR(Y24/W24,"") -> 0 | AF24: =IFERROR(X24/W24,"") -> 0 | AG24: =IFERROR(T24/W24,"") -> 0.66666667 | AH24: =IFERROR(Z24/W24,"") -> 0 | AI24: =SUM(AI19,AI20,AI21,AI22) -> 0 | AJ24: =SUM(AJ19,AJ20,AJ21,AJ22) -> 0 | AK24: =SUM(AK19,AK20,AK21,AK22) -> 0 | AL24: =SUM(AL19,AL20,AL21,AL22) -> 0 | AM24: =SUM(AM19,AM20,AM21,AM22) -> 0 | AN24: =SUM(AN19,AN20,AN21,AN22) -> 0 | AO24: =SUM(AO19,AO20,AO21,AO22) -> 0 | AP24: =IFERROR(AJ24/AI24,"") | AQ24: =IFERROR(AK24/AJ24,"") | AR24: =IFERROR(AL24/AK24,"") | AS24: =IFERROR(AL24/AJ24,"") | AT24: =IFERROR(AN24/AL24,"") | AU24: =IFERROR(AM24/AL24,"") | AV24: =IFERROR(AI24/AL24,"") | AW24: =IFERROR(AO24/AL24,"") | AX24: =SUM(AX19,AX20,AX21,AX22) -> 32 | AY24: =SUM(AY19,AY20,AY21,AY22) -> 0 | AZ24: =SUM(AZ19,AZ20,AZ21,AZ22) -> 0 | BA24: =SUM(BA19,BA20,BA21,BA22) -> 1 | BB24: =IFERROR(AY24/AX24,"") -> 0 | BC24: =IFERROR(AZ24/AX24,"") -> 0 | BD24: =IFERROR(BA24/AX24,"") -> 0.03125
A26: 44927 | B26: =SUM(David!B26,Dave!B26,'Setter 5'!B26,Rosalie!B26,'Setter 8'!B26,'Setter 7'!B26,'Setter 6'!B26,Fabien!B26,'Setter 9'!B26,'Setter 10'!B26) -> 0 | C26: =SUM(David!C26,Dave!C26,'Setter 5'!C26,Rosalie!C26,'Setter 8'!C26,'Setter 7'!C26,'Setter 6'!C26,Fabien!C26,'Setter 9'!C26,'Setter 10'!C26) -> 0 | D26: =SUM(David!D26,Dave!D26,'Setter 5'!D26,Rosalie!D26,'Setter 8'!D26,'Setter 7'!D26,'Setter 6'!D26,Fabien!D26,'Setter 9'!D26,'Setter 10'!D26) -> 0 | E26: =SUM(David!E26,Dave!E26,'Setter 5'!E26,Rosalie!E26,'Setter 8'!E26,'Setter 7'!E26,'Setter 6'!E26,Fabien!E26,'Setter 9'!E26,'Setter 10'!E26) -> 0 | F26: =SUM(David!F26,Dave!F26,'Setter 5'!F26,Rosalie!F26,'Setter 8'!F26,'Setter 7'!F26,'Setter 6'!F26,Fabien!F26,'Setter 9'!F26,'Setter 10'!F26) -> 0 | G26: =SUM(David!G26,Dave!G26,'Setter 5'!G26,Rosalie!G26,'Setter 8'!G26,'Setter 7'!G26,'Setter 6'!G26,Fabien!G26,'Setter 9'!G26,'Setter 10'!G26) -> 0 | H26: =SUM(David!H26,Dave!H26,'Setter 5'!H26,Rosalie!H26,'Setter 8'!H26,'Setter 7'!H26,'Setter 6'!H26,Fabien!H26,'Setter 9'!H26,'Setter 10'!H26) -> 0 | I26: =SUM(David!I26,Dave!I26,'Setter 5'!I26,Rosalie!I26,'Setter 8'!I26,'Setter 7'!I26,'Setter 6'!I26,Fabien!I26,'Setter 9'!I26,'Setter 10'!I26) -> 0 | J26: =SUM(David!J26,Dave!G26,'Setter 5'!G26,Rosalie!G26,'Setter 8'!G26,'Setter 7'!G26,'Setter 6'!G26,Fabien!G26,'Setter 9'!G26,'Setter 10'!G26) -> 0 | K26: =IFERROR(C26/B26,"") | L26: =IFERROR(D26/(C26-E26),"") | M26: =IFERROR(F26/(C26-E26),"") | N26: =IFERROR(G26/(C26-E26),"") | O26: =IFERROR((C26-E26)/C26,"") | P26: =IFERROR(H26/D26,"") | Q26: =IFERROR(I26/D26,"") | R26: =IFERROR(B26/D26,"") | S26: =IFERROR(J26/D26,"") | T26: =SUM(David!T26,Dave!O26,'Setter 5'!O26,Rosalie!O26,'Setter 8'!O26,'Setter 7'!O26,'Setter 6'!O26,Fabien!O26,'Setter 9'!O26,'Setter 10'!O26) -> 0 | U26: =SUM(David!U26,Dave!P26,'Setter 5'!P26,Rosalie!P26,'Setter 8'!P26,'Setter 7'!P26,'Setter 6'!P26,Fabien!P26,'Setter 9'!P26,'Setter 10'!P26) -> 0 | V26: =SUM(David!V26,Dave!Q26,'Setter 5'!Q26,Rosalie!Q26,'Setter 8'!Q26,'Setter 7'!Q26,'Setter 6'!Q26,Fabien!Q26,'Setter 9'!Q26,'Setter 10'!Q26) -> 0 | W26: =SUM(David!W26,Dave!R26,'Setter 5'!R26,Rosalie!R26,'Setter 8'!R26,'Setter 7'!R26,'Setter 6'!R26,Fabien!R26,'Setter 9'!R26,'Setter 10'!R26) -> 0 | X26: =SUM(David!X26,Dave!S26,'Setter 5'!S26,Rosalie!S26,'Setter 8'!S26,'Setter 7'!S26,'Setter 6'!S26,Fabien!S26,'Setter 9'!S26,'Setter 10'!S26) -> 0 | Y26: =SUM(David!Y26,Dave!T26,'Setter 5'!T26,Rosalie!T26,'Setter 8'!T26,'Setter 7'!T26,'Setter 6'!T26,Fabien!T26,'Setter 9'!T26,'Setter 10'!T26) -> 0 | Z26: =SUM(David!Z26,Dave!U26,'Setter 5'!U26,Rosalie!U26,'Setter 8'!U26,'Setter 7'!U26,'Setter 6'!U26,Fabien!U26,'Setter 9'!U26,'Setter 10'!U26) -> 0 | AA26: =IFERROR(U26/T26,"") | AB26: =IFERROR(V26/U26,"") | AC26: =IFERROR(W26/V26,"") | AD26: =IFERROR(W26/U26,"") | AE26: =IFERROR(Y26/W26,"") | AF26: =IFERROR(X26/W26,"") | AG26: =IFERROR(T26/W26,"") | AH26: =IFERROR(Z26/W26,"") | AI26: =SUM(David!AI26,Dave!AB26,'Setter 5'!AB26,Rosalie!AB26,'Setter 8'!AB26,'Setter 7'!AB26,'Setter 6'!AB26,Fabien!AB26,'Setter 9'!AB26,'Setter 10'!AB26) -> 0 | AJ26: =SUM(David!AJ26,Dave!AC26,'Setter 5'!AC26,Rosalie!AC26,'Setter 8'!AC26,'Setter 7'!AC26,'Setter 6'!AC26,Fabien!AC26,'Setter 9'!AC26,'Setter 10'!AC26) -> 0 | AK26: =SUM(David!AK26,Dave!AD26,'Setter 5'!AD26,Rosalie!AD26,'Setter 8'!AD26,'Setter 7'!AD26,'Setter 6'!AD26,Fabien!AD26,'Setter 9'!AD26,'Setter 10'!AD26) -> 0 | AL26: =SUM(David!AL26,Dave!AE26,'Setter 5'!AE26,Rosalie!AE26,'Setter 8'!AE26,'Setter 7'!AE26,'Setter 6'!AE26,Fabien!AE26,'Setter 9'!AE26,'Setter 10'!AE26) -> 0 | AM26: =SUM(David!AM26,Dave!AF26,'Setter 5'!AF26,Rosalie!AF26,'Setter 8'!AF26,'Setter 7'!AF26,'Setter 6'!AF26,Fabien!AF26,'Setter 9'!AF26,'Setter 10'!AF26) -> 0 | AN26: =SUM(David!AN26,Dave!AG26,'Setter 5'!AG26,Rosalie!AG26,'Setter 8'!AG26,'Setter 7'!AG26,'Setter 6'!AG26,Fabien!AG26,'Setter 9'!AG26,'Setter 10'!AG26) -> 0 | AO26: =SUM(David!AO26,Dave!AH26,'Setter 5'!AH26,Rosalie!AH26,'Setter 8'!AH26,'Setter 7'!AH26,'Setter 6'!AH26,Fabien!AH26,'Setter 9'!AH26,'Setter 10'!AH26) -> 0 | AP26: =IFERROR(AO26/AI26,"") | AQ26: =IFERROR(AJ26/AI26,"") | AX26: =T26+B26+AI26 -> 0 | AY26: =AM26+X26+H26 -> 0 | AZ26: =AN26+I26 -> 0 | BA26: =AO26+J26 -> 0 | BB26: =IFERROR(AY26/AX26,"") | BC26: =IFERROR(AZ26/AX26,"") | BD26: =IFERROR(BA26/AX26,"")
A27: 44928 | B27: =SUM(David!B27,Dave!B27,'Setter 5'!B27,Rosalie!B27,'Setter 8'!B27,'Setter 7'!B27,'Setter 6'!B27,Fabien!B27,'Setter 9'!B27,'Setter 10'!B27) -> 0 | C27: =SUM(David!C27,Dave!C27,'Setter 5'!C27,Rosalie!C27,'Setter 8'!C27,'Setter 7'!C27,'Setter 6'!C27,Fabien!C27,'Setter 9'!C27,'Setter 10'!C27) -> 0 | D27: =SUM(David!D27,Dave!D27,'Setter 5'!D27,Rosalie!D27,'Setter 8'!D27,'Setter 7'!D27,'Setter 6'!D27,Fabien!D27,'Setter 9'!D27,'Setter 10'!D27) -> 0 | E27: =SUM(David!E27,Dave!E27,'Setter 5'!E27,Rosalie!E27,'Setter 8'!E27,'Setter 7'!E27,'Setter 6'!E27,Fabien!E27,'Setter 9'!E27,'Setter 10'!E27) -> 0 | F27: =SUM(David!F27,Dave!F27,'Setter 5'!F27,Rosalie!F27,'Setter 8'!F27,'Setter 7'!F27,'Setter 6'!F27,Fabien!F27,'Setter 9'!F27,'Setter 10'!F27) -> 0 | G27: =SUM(David!G27,Dave!G27,'Setter 5'!G27,Rosalie!G27,'Setter 8'!G27,'Setter 7'!G27,'Setter 6'!G27,Fabien!G27,'Setter 9'!G27,'Setter 10'!G27) -> 0 | H27: =SUM(David!H27,Dave!H27,'Setter 5'!H27,Rosalie!H27,'Setter 8'!H27,'Setter 7'!H27,'Setter 6'!H27,Fabien!H27,'Setter 9'!H27,'Setter 10'!H27) -> 0 | I27: =SUM(David!I27,Dave!I27,'Setter 5'!I27,Rosalie!I27,'Setter 8'!I27,'Setter 7'!I27,'Setter 6'!I27,Fabien!I27,'Setter 9'!I27,'Setter 10'!I27) -> 0 | J27: =SUM(David!J27,Dave!G27,'Setter 5'!G27,Rosalie!G27,'Setter 8'!G27,'Setter 7'!G27,'Setter 6'!G27,Fabien!G27,'Setter 9'!G27,'Setter 10'!G27) -> 0 | K27: =IFERROR(C27/B27,"") | L27: =IFERROR(D27/(C27-E27),"") | M27: =IFERROR(F27/(C27-E27),"") | N27: =IFERROR(G27/(C27-E27),"") | O27: =IFERROR((C27-E27)/C27,"") | P27: =IFERROR(H27/D27,"") | Q27: =IFERROR(I27/D27,"") | R27: =IFERROR(B27/D27,"") | S27: =IFERROR(J27/D27,"") | T27: =SUM(David!T27,Dave!O27,'Setter 5'!O27,Rosalie!O27,'Setter 8'!O27,'Setter 7'!O27,'Setter 6'!O27,Fabien!O27,'Setter 9'!O27,'Setter 10'!O27) -> 0 | U27: =SUM(David!U27,Dave!P27,'Setter 5'!P27,Rosalie!P27,'Setter 8'!P27,'Setter 7'!P27,'Setter 6'!P27,Fabien!P27,'Setter 9'!P27,'Setter 10'!P27) -> 0 | V27: =SUM(David!V27,Dave!Q27,'Setter 5'!Q27,Rosalie!Q27,'Setter 8'!Q27,'Setter 7'!Q27,'Setter 6'!Q27,Fabien!Q27,'Setter 9'!Q27,'Setter 10'!Q27) -> 0 | W27: =SUM(David!W27,Dave!R27,'Setter 5'!R27,Rosalie!R27,'Setter 8'!R27,'Setter 7'!R27,'Setter 6'!R27,Fabien!R27,'Setter 9'!R27,'Setter 10'!R27) -> 0 | X27: =SUM(David!X27,Dave!S27,'Setter 5'!S27,Rosalie!S27,'Setter 8'!S27,'Setter 7'!S27,'Setter 6'!S27,Fabien!S27,'Setter 9'!S27,'Setter 10'!S27) -> 0 | Y27: =SUM(David!Y27,Dave!T27,'Setter 5'!T27,Rosalie!T27,'Setter 8'!T27,'Setter 7'!T27,'Setter 6'!T27,Fabien!T27,'Setter 9'!T27,'Setter 10'!T27) -> 0 | Z27: =SUM(David!Z27,Dave!U27,'Setter 5'!U27,Rosalie!U27,'Setter 8'!U27,'Setter 7'!U27,'Setter 6'!U27,Fabien!U27,'Setter 9'!U27,'Setter 10'!U27) -> 0 | AA27: =IFERROR(U27/T27,"") | AB27: =IFERROR(V27/U27,"") | AC27: =IFERROR(W27/V27,"") | AD27: =IFERROR(W27/U27,"") | AE27: =IFERROR(Y27/W27,"") | AF27: =IFERROR(X27/W27,"") | AG27: =IFERROR(T27/W27,"") | AH27: =IFERROR(Z27/W27,"") | AI27: =SUM(David!AI27,Dave!AB27,'Setter 5'!AB27,Rosalie!AB27,'Setter 8'!AB27,'Setter 7'!AB27,'Setter 6'!AB27,Fabien!AB27,'Setter 9'!AB27,'Setter 10'!AB27) -> 0 | AJ27: =SUM(David!AJ27,Dave!AC27,'Setter 5'!AC27,Rosalie!AC27,'Setter 8'!AC27,'Setter 7'!AC27,'Setter 6'!AC27,Fabien!AC27,'Setter 9'!AC27,'Setter 10'!AC27) -> 0 | AK27: =SUM(David!AK27,Dave!AD27,'Setter 5'!AD27,Rosalie!AD27,'Setter 8'!AD27,'Setter 7'!AD27,'Setter 6'!AD27,Fabien!AD27,'Setter 9'!AD27,'Setter 10'!AD27) -> 0 | AL27: =SUM(David!AL27,Dave!AE27,'Setter 5'!AE27,Rosalie!AE27,'Setter 8'!AE27,'Setter 7'!AE27,'Setter 6'!AE27,Fabien!AE27,'Setter 9'!AE27,'Setter 10'!AE27) -> 0 | AM27: =SUM(David!AM27,Dave!AF27,'Setter 5'!AF27,Rosalie!AF27,'Setter 8'!AF27,'Setter 7'!AF27,'Setter 6'!AF27,Fabien!AF27,'Setter 9'!AF27,'Setter 10'!AF27) -> 0 | AN27: =SUM(David!AN27,Dave!AG27,'Setter 5'!AG27,Rosalie!AG27,'Setter 8'!AG27,'Setter 7'!AG27,'Setter 6'!AG27,Fabien!AG27,'Setter 9'!AG27,'Setter 10'!AG27) -> 0 | AO27: =SUM(David!AO27,Dave!AH27,'Setter 5'!AH27,Rosalie!AH27,'Setter 8'!AH27,'Setter 7'!AH27,'Setter 6'!AH27,Fabien!AH27,'Setter 9'!AH27,'Setter 10'!AH27) -> 0 | AP27: =IFERROR(AO27/AI27,"") | AQ27: =IFERROR(AJ27/AI27,"") | AX27: =T27+B27+AI27 -> 0 | AY27: =AM27+X27+H27 -> 0 | AZ27: =AN27+I27 -> 0 | BA27: =AO27+J27 -> 0 | BB27: =IFERROR(AY27/AX27,"") | BC27: =IFERROR(AZ27/AX27,"") | BD27: =IFERROR(BA27/AX27,"")
A28: 44929 | B28: =SUM(David!B28,Dave!B28,'Setter 5'!B28,Rosalie!B28,'Setter 8'!B28,'Setter 7'!B28,'Setter 6'!B28,Fabien!B28,'Setter 9'!B28,'Setter 10'!B28) -> 0 | C28: =SUM(David!C28,Dave!C28,'Setter 5'!C28,Rosalie!C28,'Setter 8'!C28,'Setter 7'!C28,'Setter 6'!C28,Fabien!C28,'Setter 9'!C28,'Setter 10'!C28) -> 0 | D28: =SUM(David!D28,Dave!D28,'Setter 5'!D28,Rosalie!D28,'Setter 8'!D28,'Setter 7'!D28,'Setter 6'!D28,Fabien!D28,'Setter 9'!D28,'Setter 10'!D28) -> 0 | E28: =SUM(David!E28,Dave!E28,'Setter 5'!E28,Rosalie!E28,'Setter 8'!E28,'Setter 7'!E28,'Setter 6'!E28,Fabien!E28,'Setter 9'!E28,'Setter 10'!E28) -> 0 | F28: =SUM(David!F28,Dave!F28,'Setter 5'!F28,Rosalie!F28,'Setter 8'!F28,'Setter 7'!F28,'Setter 6'!F28,Fabien!F28,'Setter 9'!F28,'Setter 10'!F28) -> 0 | G28: =SUM(David!G28,Dave!G28,'Setter 5'!G28,Rosalie!G28,'Setter 8'!G28,'Setter 7'!G28,'Setter 6'!G28,Fabien!G28,'Setter 9'!G28,'Setter 10'!G28) -> 0 | H28: =SUM(David!H28,Dave!H28,'Setter 5'!H28,Rosalie!H28,'Setter 8'!H28,'Setter 7'!H28,'Setter 6'!H28,Fabien!H28,'Setter 9'!H28,'Setter 10'!H28) -> 0 | I28: =SUM(David!I28,Dave!I28,'Setter 5'!I28,Rosalie!I28,'Setter 8'!I28,'Setter 7'!I28,'Setter 6'!I28,Fabien!I28,'Setter 9'!I28,'Setter 10'!I28) -> 0 | J28: =SUM(David!J28,Dave!G28,'Setter 5'!G28,Rosalie!G28,'Setter 8'!G28,'Setter 7'!G28,'Setter 6'!G28,Fabien!G28,'Setter 9'!G28,'Setter 10'!G28) -> 0 | K28: =IFERROR(C28/B28,"") | L28: =IFERROR(D28/(C28-E28),"") | M28: =IFERROR(F28/(C28-E28),"") | N28: =IFERROR(G28/(C28-E28),"") | O28: =IFERROR((C28-E28)/C28,"") | P28: =IFERROR(H28/D28,"") | Q28: =IFERROR(I28/D28,"") | R28: =IFERROR(B28/D28,"") | S28: =IFERROR(J28/D28,"") | T28: =SUM(David!T28,Dave!O28,'Setter 5'!O28,Rosalie!O28,'Setter 8'!O28,'Setter 7'!O28,'Setter 6'!O28,Fabien!O28,'Setter 9'!O28,'Setter 10'!O28) -> 0 | U28: =SUM(David!U28,Dave!P28,'Setter 5'!P28,Rosalie!P28,'Setter 8'!P28,'Setter 7'!P28,'Setter 6'!P28,Fabien!P28,'Setter 9'!P28,'Setter 10'!P28) -> 0 | V28: =SUM(David!V28,Dave!Q28,'Setter 5'!Q28,Rosalie!Q28,'Setter 8'!Q28,'Setter 7'!Q28,'Setter 6'!Q28,Fabien!Q28,'Setter 9'!Q28,'Setter 10'!Q28) -> 0 | W28: =SUM(David!W28,Dave!R28,'Setter 5'!R28,Rosalie!R28,'Setter 8'!R28,'Setter 7'!R28,'Setter 6'!R28,Fabien!R28,'Setter 9'!R28,'Setter 10'!R28) -> 0 | X28: =SUM(David!X28,Dave!S28,'Setter 5'!S28,Rosalie!S28,'Setter 8'!S28,'Setter 7'!S28,'Setter 6'!S28,Fabien!S28,'Setter 9'!S28,'Setter 10'!S28) -> 0 | Y28: =SUM(David!Y28,Dave!T28,'Setter 5'!T28,Rosalie!T28,'Setter 8'!T28,'Setter 7'!T28,'Setter 6'!T28,Fabien!T28,'Setter 9'!T28,'Setter 10'!T28) -> 0 | Z28: =SUM(David!Z28,Dave!U28,'Setter 5'!U28,Rosalie!U28,'Setter 8'!U28,'Setter 7'!U28,'Setter 6'!U28,Fabien!U28,'Setter 9'!U28,'Setter 10'!U28) -> 0 | AA28: =IFERROR(U28/T28,"") | AB28: =IFERROR(V28/U28,"") | AC28: =IFERROR(W28/V28,"") | AD28: =IFERROR(W28/U28,"") | AE28: =IFERROR(Y28/W28,"") | AF28: =IFERROR(X28/W28,"") | AG28: =IFERROR(T28/W28,"") | AH28: =IFERROR(Z28/W28,"") | AI28: =SUM(David!AI28,Dave!AB28,'Setter 5'!AB28,Rosalie!AB28,'Setter 8'!AB28,'Setter 7'!AB28,'Setter 6'!AB28,Fabien!AB28,'Setter 9'!AB28,'Setter 10'!AB28) -> 0 | AJ28: =SUM(David!AJ28,Dave!AC28,'Setter 5'!AC28,Rosalie!AC28,'Setter 8'!AC28,'Setter 7'!AC28,'Setter 6'!AC28,Fabien!AC28,'Setter 9'!AC28,'Setter 10'!AC28) -> 0 | AK28: =SUM(David!AK28,Dave!AD28,'Setter 5'!AD28,Rosalie!AD28,'Setter 8'!AD28,'Setter 7'!AD28,'Setter 6'!AD28,Fabien!AD28,'Setter 9'!AD28,'Setter 10'!AD28) -> 0 | AL28: =SUM(David!AL28,Dave!AE28,'Setter 5'!AE28,Rosalie!AE28,'Setter 8'!AE28,'Setter 7'!AE28,'Setter 6'!AE28,Fabien!AE28,'Setter 9'!AE28,'Setter 10'!AE28) -> 0 | AM28: =SUM(David!AM28,Dave!AF28,'Setter 5'!AF28,Rosalie!AF28,'Setter 8'!AF28,'Setter 7'!AF28,'Setter 6'!AF28,Fabien!AF28,'Setter 9'!AF28,'Setter 10'!AF28) -> 0 | AN28: =SUM(David!AN28,Dave!AG28,'Setter 5'!AG28,Rosalie!AG28,'Setter 8'!AG28,'Setter 7'!AG28,'Setter 6'!AG28,Fabien!AG28,'Setter 9'!AG28,'Setter 10'!AG28) -> 0 | AO28: =SUM(David!AO28,Dave!AH28,'Setter 5'!AH28,Rosalie!AH28,'Setter 8'!AH28,'Setter 7'!AH28,'Setter 6'!AH28,Fabien!AH28,'Setter 9'!AH28,'Setter 10'!AH28) -> 0 | AP28: =IFERROR(AO28/AI28,"") | AQ28: =IFERROR(AJ28/AI28,"") | AX28: =T28+B28+AI28 -> 0 | AY28: =AM28+X28+H28 -> 0 | AZ28: =AN28+I28 -> 0 | BA28: =AO28+J28 -> 0 | BB28: =IFERROR(AY28/AX28,"") | BC28: =IFERROR(AZ28/AX28,"") | BD28: =IFERROR(BA28/AX28,"")
A29: 44930 | B29: =SUM(David!B29,Dave!B29,'Setter 5'!B29,Rosalie!B29,'Setter 8'!B29,'Setter 7'!B29,'Setter 6'!B29,Fabien!B29,'Setter 9'!B29,'Setter 10'!B29) -> 0 | C29: =SUM(David!C29,Dave!C29,'Setter 5'!C29,Rosalie!C29,'Setter 8'!C29,'Setter 7'!C29,'Setter 6'!C29,Fabien!C29,'Setter 9'!C29,'Setter 10'!C29) -> 0 | D29: =SUM(David!D29,Dave!D29,'Setter 5'!D29,Rosalie!D29,'Setter 8'!D29,'Setter 7'!D29,'Setter 6'!D29,Fabien!D29,'Setter 9'!D29,'Setter 10'!D29) -> 0 | E29: =SUM(David!E29,Dave!E29,'Setter 5'!E29,Rosalie!E29,'Setter 8'!E29,'Setter 7'!E29,'Setter 6'!E29,Fabien!E29,'Setter 9'!E29,'Setter 10'!E29) -> 0 | F29: =SUM(David!F29,Dave!F29,'Setter 5'!F29,Rosalie!F29,'Setter 8'!F29,'Setter 7'!F29,'Setter 6'!F29,Fabien!F29,'Setter 9'!F29,'Setter 10'!F29) -> 0 | G29: =SUM(David!G29,Dave!G29,'Setter 5'!G29,Rosalie!G29,'Setter 8'!G29,'Setter 7'!G29,'Setter 6'!G29,Fabien!G29,'Setter 9'!G29,'Setter 10'!G29) -> 0 | H29: =SUM(David!H29,Dave!H29,'Setter 5'!H29,Rosalie!H29,'Setter 8'!H29,'Setter 7'!H29,'Setter 6'!H29,Fabien!H29,'Setter 9'!H29,'Setter 10'!H29) -> 0 | I29: =SUM(David!I29,Dave!I29,'Setter 5'!I29,Rosalie!I29,'Setter 8'!I29,'Setter 7'!I29,'Setter 6'!I29,Fabien!I29,'Setter 9'!I29,'Setter 10'!I29) -> 0 | J29: =SUM(David!J29,Dave!G29,'Setter 5'!G29,Rosalie!G29,'Setter 8'!G29,'Setter 7'!G29,'Setter 6'!G29,Fabien!G29,'Setter 9'!G29,'Setter 10'!G29) -> 0 | K29: =IFERROR(C29/B29,"") | L29: =IFERROR(D29/(C29-E29),"") | M29: =IFERROR(F29/(C29-E29),"") | N29: =IFERROR(G29/(C29-E29),"") | O29: =IFERROR((C29-E29)/C29,"") | P29: =IFERROR(H29/D29,"") | Q29: =IFERROR(I29/D29,"") | R29: =IFERROR(B29/D29,"") | S29: =IFERROR(J29/D29,"") | T29: =SUM(David!T29,Dave!O29,'Setter 5'!O29,Rosalie!O29,'Setter 8'!O29,'Setter 7'!O29,'Setter 6'!O29,Fabien!O29,'Setter 9'!O29,'Setter 10'!O29) -> 0 | U29: =SUM(David!U29,Dave!P29,'Setter 5'!P29,Rosalie!P29,'Setter 8'!P29,'Setter 7'!P29,'Setter 6'!P29,Fabien!P29,'Setter 9'!P29,'Setter 10'!P29) -> 0 | V29: =SUM(David!V29,Dave!Q29,'Setter 5'!Q29,Rosalie!Q29,'Setter 8'!Q29,'Setter 7'!Q29,'Setter 6'!Q29,Fabien!Q29,'Setter 9'!Q29,'Setter 10'!Q29) -> 0 | W29: =SUM(David!W29,Dave!R29,'Setter 5'!R29,Rosalie!R29,'Setter 8'!R29,'Setter 7'!R29,'Setter 6'!R29,Fabien!R29,'Setter 9'!R29,'Setter 10'!R29) -> 0 | X29: =SUM(David!X29,Dave!S29,'Setter 5'!S29,Rosalie!S29,'Setter 8'!S29,'Setter 7'!S29,'Setter 6'!S29,Fabien!S29,'Setter 9'!S29,'Setter 10'!S29) -> 0 | Y29: =SUM(David!Y29,Dave!T29,'Setter 5'!T29,Rosalie!T29,'Setter 8'!T29,'Setter 7'!T29,'Setter 6'!T29,Fabien!T29,'Setter 9'!T29,'Setter 10'!T29) -> 0 | Z29: =SUM(David!Z29,Dave!U29,'Setter 5'!U29,Rosalie!U29,'Setter 8'!U29,'Setter 7'!U29,'Setter 6'!U29,Fabien!U29,'Setter 9'!U29,'Setter 10'!U29) -> 0 | AA29: =IFERROR(U29/T29,"") | AB29: =IFERROR(V29/U29,"") | AC29: =IFERROR(W29/V29,"") | AD29: =IFERROR(W29/U29,"") | AE29: =IFERROR(Y29/W29,"") | AF29: =IFERROR(X29/W29,"") | AG29: =IFERROR(T29/W29,"") | AH29: =IFERROR(Z29/W29,"") | AI29: =SUM(David!AI29,Dave!AB29,'Setter 5'!AB29,Rosalie!AB29,'Setter 8'!AB29,'Setter 7'!AB29,'Setter 6'!AB29,Fabien!AB29,'Setter 9'!AB29,'Setter 10'!AB29) -> 0 | AJ29: =SUM(David!AJ29,Dave!AC29,'Setter 5'!AC29,Rosalie!AC29,'Setter 8'!AC29,'Setter 7'!AC29,'Setter 6'!AC29,Fabien!AC29,'Setter 9'!AC29,'Setter 10'!AC29) -> 0 | AK29: =SUM(David!AK29,Dave!AD29,'Setter 5'!AD29,Rosalie!AD29,'Setter 8'!AD29,'Setter 7'!AD29,'Setter 6'!AD29,Fabien!AD29,'Setter 9'!AD29,'Setter 10'!AD29) -> 0 | AL29: =SUM(David!AL29,Dave!AE29,'Setter 5'!AE29,Rosalie!AE29,'Setter 8'!AE29,'Setter 7'!AE29,'Setter 6'!AE29,Fabien!AE29,'Setter 9'!AE29,'Setter 10'!AE29) -> 0 | AM29: =SUM(David!AM29,Dave!AF29,'Setter 5'!AF29,Rosalie!AF29,'Setter 8'!AF29,'Setter 7'!AF29,'Setter 6'!AF29,Fabien!AF29,'Setter 9'!AF29,'Setter 10'!AF29) -> 0 | AN29: =SUM(David!AN29,Dave!AG29,'Setter 5'!AG29,Rosalie!AG29,'Setter 8'!AG29,'Setter 7'!AG29,'Setter 6'!AG29,Fabien!AG29,'Setter 9'!AG29,'Setter 10'!AG29) -> 0 | AO29: =SUM(David!AO29,Dave!AH29,'Setter 5'!AH29,Rosalie!AH29,'Setter 8'!AH29,'Setter 7'!AH29,'Setter 6'!AH29,Fabien!AH29,'Setter 9'!AH29,'Setter 10'!AH29) -> 0 | AP29: =IFERROR(AO29/AI29,"") | AQ29: =IFERROR(AJ29/AI29,"") | AX29: =T29+B29+AI29 -> 0 | AY29: =AM29+X29+H29 -> 0 | AZ29: =AN29+I29 -> 0 | BA29: =AO29+J29 -> 0 | BB29: =IFERROR(AY29/AX29,"") | BC29: =IFERROR(AZ29/AX29,"") | BD29: =IFERROR(BA29/AX29,"")
A30: 44931 | B30: =SUM(David!B30,Dave!B30,'Setter 5'!B30,Rosalie!B30,'Setter 8'!B30,'Setter 7'!B30,'Setter 6'!B30,Fabien!B30,'Setter 9'!B30,'Setter 10'!B30) -> 0 | C30: =SUM(David!C30,Dave!C30,'Setter 5'!C30,Rosalie!C30,'Setter 8'!C30,'Setter 7'!C30,'Setter 6'!C30,Fabien!C30,'Setter 9'!C30,'Setter 10'!C30) -> 0 | D30: =SUM(David!D30,Dave!D30,'Setter 5'!D30,Rosalie!D30,'Setter 8'!D30,'Setter 7'!D30,'Setter 6'!D30,Fabien!D30,'Setter 9'!D30,'Setter 10'!D30) -> 0 | E30: =SUM(David!E30,Dave!E30,'Setter 5'!E30,Rosalie!E30,'Setter 8'!E30,'Setter 7'!E30,'Setter 6'!E30,Fabien!E30,'Setter 9'!E30,'Setter 10'!E30) -> 0 | F30: =SUM(David!F30,Dave!F30,'Setter 5'!F30,Rosalie!F30,'Setter 8'!F30,'Setter 7'!F30,'Setter 6'!F30,Fabien!F30,'Setter 9'!F30,'Setter 10'!F30) -> 0 | G30: =SUM(David!G30,Dave!G30,'Setter 5'!G30,Rosalie!G30,'Setter 8'!G30,'Setter 7'!G30,'Setter 6'!G30,Fabien!G30,'Setter 9'!G30,'Setter 10'!G30) -> 0 | H30: =SUM(David!H30,Dave!H30,'Setter 5'!H30,Rosalie!H30,'Setter 8'!H30,'Setter 7'!H30,'Setter 6'!H30,Fabien!H30,'Setter 9'!H30,'Setter 10'!H30) -> 0 | I30: =SUM(David!I30,Dave!I30,'Setter 5'!I30,Rosalie!I30,'Setter 8'!I30,'Setter 7'!I30,'Setter 6'!I30,Fabien!I30,'Setter 9'!I30,'Setter 10'!I30) -> 0 | J30: =SUM(David!J30,Dave!G30,'Setter 5'!G30,Rosalie!G30,'Setter 8'!G30,'Setter 7'!G30,'Setter 6'!G30,Fabien!G30,'Setter 9'!G30,'Setter 10'!G30) -> 0 | K30: =IFERROR(C30/B30,"") | L30: =IFERROR(D30/(C30-E30),"") | M30: =IFERROR(F30/(C30-E30),"") | N30: =IFERROR(G30/(C30-E30),"") | O30: =IFERROR((C30-E30)/C30,"") | P30: =IFERROR(H30/D30,"") | Q30: =IFERROR(I30/D30,"") | R30: =IFERROR(B30/D30,"") | S30: =IFERROR(J30/D30,"") | T30: =SUM(David!T30,Dave!O30,'Setter 5'!O30,Rosalie!O30,'Setter 8'!O30,'Setter 7'!O30,'Setter 6'!O30,Fabien!O30,'Setter 9'!O30,'Setter 10'!O30) -> 0 | U30: =SUM(David!U30,Dave!P30,'Setter 5'!P30,Rosalie!P30,'Setter 8'!P30,'Setter 7'!P30,'Setter 6'!P30,Fabien!P30,'Setter 9'!P30,'Setter 10'!P30) -> 0 | V30: =SUM(David!V30,Dave!Q30,'Setter 5'!Q30,Rosalie!Q30,'Setter 8'!Q30,'Setter 7'!Q30,'Setter 6'!Q30,Fabien!Q30,'Setter 9'!Q30,'Setter 10'!Q30) -> 0 | W30: =SUM(David!W30,Dave!R30,'Setter 5'!R30,Rosalie!R30,'Setter 8'!R30,'Setter 7'!R30,'Setter 6'!R30,Fabien!R30,'Setter 9'!R30,'Setter 10'!R30) -> 0 | X30: =SUM(David!X30,Dave!S30,'Setter 5'!S30,Rosalie!S30,'Setter 8'!S30,'Setter 7'!S30,'Setter 6'!S30,Fabien!S30,'Setter 9'!S30,'Setter 10'!S30) -> 0 | Y30: =SUM(David!Y30,Dave!T30,'Setter 5'!T30,Rosalie!T30,'Setter 8'!T30,'Setter 7'!T30,'Setter 6'!T30,Fabien!T30,'Setter 9'!T30,'Setter 10'!T30) -> 0 | Z30: =SUM(David!Z30,Dave!U30,'Setter 5'!U30,Rosalie!U30,'Setter 8'!U30,'Setter 7'!U30,'Setter 6'!U30,Fabien!U30,'Setter 9'!U30,'Setter 10'!U30) -> 0 | AA30: =IFERROR(U30/T30,"") | AB30: =IFERROR(V30/U30,"") | AC30: =IFERROR(W30/V30,"") | AD30: =IFERROR(W30/U30,"") | AE30: =IFERROR(Y30/W30,"") | AF30: =IFERROR(X30/W30,"") | AG30: =IFERROR(T30/W30,"") | AH30: =IFERROR(Z30/W30,"") | AI30: =SUM(David!AI30,Dave!AB30,'Setter 5'!AB30,Rosalie!AB30,'Setter 8'!AB30,'Setter 7'!AB30,'Setter 6'!AB30,Fabien!AB30,'Setter 9'!AB30,'Setter 10'!AB30) -> 0 | AJ30: =SUM(David!AJ30,Dave!AC30,'Setter 5'!AC30,Rosalie!AC30,'Setter 8'!AC30,'Setter 7'!AC30,'Setter 6'!AC30,Fabien!AC30,'Setter 9'!AC30,'Setter 10'!AC30) -> 0 | AK30: =SUM(David!AK30,Dave!AD30,'Setter 5'!AD30,Rosalie!AD30,'Setter 8'!AD30,'Setter 7'!AD30,'Setter 6'!AD30,Fabien!AD30,'Setter 9'!AD30,'Setter 10'!AD30) -> 0 | AL30: =SUM(David!AL30,Dave!AE30,'Setter 5'!AE30,Rosalie!AE30,'Setter 8'!AE30,'Setter 7'!AE30,'Setter 6'!AE30,Fabien!AE30,'Setter 9'!AE30,'Setter 10'!AE30) -> 0 | AM30: =SUM(David!AM30,Dave!AF30,'Setter 5'!AF30,Rosalie!AF30,'Setter 8'!AF30,'Setter 7'!AF30,'Setter 6'!AF30,Fabien!AF30,'Setter 9'!AF30,'Setter 10'!AF30) -> 0 | AN30: =SUM(David!AN30,Dave!AG30,'Setter 5'!AG30,Rosalie!AG30,'Setter 8'!AG30,'Setter 7'!AG30,'Setter 6'!AG30,Fabien!AG30,'Setter 9'!AG30,'Setter 10'!AG30) -> 0 | AO30: =SUM(David!AO30,Dave!AH30,'Setter 5'!AH30,Rosalie!AH30,'Setter 8'!AH30,'Setter 7'!AH30,'Setter 6'!AH30,Fabien!AH30,'Setter 9'!AH30,'Setter 10'!AH30) -> 0 | AP30: =IFERROR(AO30/AI30,"") | AQ30: =IFERROR(AJ30/AI30,"") | AX30: =T30+B30+AI30 -> 0 | AY30: =AM30+X30+H30 -> 0 | AZ30: =AN30+I30 -> 0 | BA30: =AO30+J30 -> 0 | BB30: =IFERROR(AY30/AX30,"") | BC30: =IFERROR(AZ30/AX30,"") | BD30: =IFERROR(BA30/AX30,"")
A31: 44932 | B31: =SUM(David!B31,Dave!B31,'Setter 5'!B31,Rosalie!B31,'Setter 8'!B31,'Setter 7'!B31,'Setter 6'!B31,Fabien!B31,'Setter 9'!B31,'Setter 10'!B31) -> 0 | C31: =SUM(David!C31,Dave!C31,'Setter 5'!C31,Rosalie!C31,'Setter 8'!C31,'Setter 7'!C31,'Setter 6'!C31,Fabien!C31,'Setter 9'!C31,'Setter 10'!C31) -> 0 | D31: =SUM(David!D31,Dave!D31,'Setter 5'!D31,Rosalie!D31,'Setter 8'!D31,'Setter 7'!D31,'Setter 6'!D31,Fabien!D31,'Setter 9'!D31,'Setter 10'!D31) -> 0 | E31: =SUM(David!E31,Dave!E31,'Setter 5'!E31,Rosalie!E31,'Setter 8'!E31,'Setter 7'!E31,'Setter 6'!E31,Fabien!E31,'Setter 9'!E31,'Setter 10'!E31) -> 0 | F31: =SUM(David!F31,Dave!F31,'Setter 5'!F31,Rosalie!F31,'Setter 8'!F31,'Setter 7'!F31,'Setter 6'!F31,Fabien!F31,'Setter 9'!F31,'Setter 10'!F31) -> 0 | G31: =SUM(David!G31,Dave!G31,'Setter 5'!G31,Rosalie!G31,'Setter 8'!G31,'Setter 7'!G31,'Setter 6'!G31,Fabien!G31,'Setter 9'!G31,'Setter 10'!G31) -> 0 | H31: =SUM(David!H31,Dave!H31,'Setter 5'!H31,Rosalie!H31,'Setter 8'!H31,'Setter 7'!H31,'Setter 6'!H31,Fabien!H31,'Setter 9'!H31,'Setter 10'!H31) -> 0 | I31: =SUM(David!I31,Dave!I31,'Setter 5'!I31,Rosalie!I31,'Setter 8'!I31,'Setter 7'!I31,'Setter 6'!I31,Fabien!I31,'Setter 9'!I31,'Setter 10'!I31) -> 0 | J31: =SUM(David!J31,Dave!G31,'Setter 5'!G31,Rosalie!G31,'Setter 8'!G31,'Setter 7'!G31,'Setter 6'!G31,Fabien!G31,'Setter 9'!G31,'Setter 10'!G31) -> 0 | K31: =IFERROR(C31/B31,"") | L31: =IFERROR(D31/(C31-E31),"") | M31: =IFERROR(F31/(C31-E31),"") | N31: =IFERROR(G31/(C31-E31),"") | O31: =IFERROR((C31-E31)/C31,"") | P31: =IFERROR(H31/D31,"") | Q31: =IFERROR(I31/D31,"") | R31: =IFERROR(B31/D31,"") | S31: =IFERROR(J31/D31,"") | T31: =SUM(David!T31,Dave!O31,'Setter 5'!O31,Rosalie!O31,'Setter 8'!O31,'Setter 7'!O31,'Setter 6'!O31,Fabien!O31,'Setter 9'!O31,'Setter 10'!O31) -> 0 | U31: =SUM(David!U31,Dave!P31,'Setter 5'!P31,Rosalie!P31,'Setter 8'!P31,'Setter 7'!P31,'Setter 6'!P31,Fabien!P31,'Setter 9'!P31,'Setter 10'!P31) -> 0 | V31: =SUM(David!V31,Dave!Q31,'Setter 5'!Q31,Rosalie!Q31,'Setter 8'!Q31,'Setter 7'!Q31,'Setter 6'!Q31,Fabien!Q31,'Setter 9'!Q31,'Setter 10'!Q31) -> 0 | W31: =SUM(David!W31,Dave!R31,'Setter 5'!R31,Rosalie!R31,'Setter 8'!R31,'Setter 7'!R31,'Setter 6'!R31,Fabien!R31,'Setter 9'!R31,'Setter 10'!R31) -> 0 | X31: =SUM(David!X31,Dave!S31,'Setter 5'!S31,Rosalie!S31,'Setter 8'!S31,'Setter 7'!S31,'Setter 6'!S31,Fabien!S31,'Setter 9'!S31,'Setter 10'!S31) -> 0 | Y31: =SUM(David!Y31,Dave!T31,'Setter 5'!T31,Rosalie!T31,'Setter 8'!T31,'Setter 7'!T31,'Setter 6'!T31,Fabien!T31,'Setter 9'!T31,'Setter 10'!T31) -> 0 | Z31: =SUM(David!Z31,Dave!U31,'Setter 5'!U31,Rosalie!U31,'Setter 8'!U31,'Setter 7'!U31,'Setter 6'!U31,Fabien!U31,'Setter 9'!U31,'Setter 10'!U31) -> 0 | AA31: =IFERROR(U31/T31,"") | AB31: =IFERROR(V31/U31,"") | AC31: =IFERROR(W31/V31,"") | AD31: =IFERROR(W31/U31,"") | AE31: =IFERROR(Y31/W31,"") | AF31: =IFERROR(X31/W31,"") | AG31: =IFERROR(T31/W31,"") | AH31: =IFERROR(Z31/W31,"") | AI31: =SUM(David!AI31,Dave!AB31,'Setter 5'!AB31,Rosalie!AB31,'Setter 8'!AB31,'Setter 7'!AB31,'Setter 6'!AB31,Fabien!AB31,'Setter 9'!AB31,'Setter 10'!AB31) -> 0 | AJ31: =SUM(David!AJ31,Dave!AC31,'Setter 5'!AC31,Rosalie!AC31,'Setter 8'!AC31,'Setter 7'!AC31,'Setter 6'!AC31,Fabien!AC31,'Setter 9'!AC31,'Setter 10'!AC31) -> 0 | AK31: =SUM(David!AK31,Dave!AD31,'Setter 5'!AD31,Rosalie!AD31,'Setter 8'!AD31,'Setter 7'!AD31,'Setter 6'!AD31,Fabien!AD31,'Setter 9'!AD31,'Setter 10'!AD31) -> 0 | AL31: =SUM(David!AL31,Dave!AE31,'Setter 5'!AE31,Rosalie!AE31,'Setter 8'!AE31,'Setter 7'!AE31,'Setter 6'!AE31,Fabien!AE31,'Setter 9'!AE31,'Setter 10'!AE31) -> 0 | AM31: =SUM(David!AM31,Dave!AF31,'Setter 5'!AF31,Rosalie!AF31,'Setter 8'!AF31,'Setter 7'!AF31,'Setter 6'!AF31,Fabien!AF31,'Setter 9'!AF31,'Setter 10'!AF31) -> 0 | AN31: =SUM(David!AN31,Dave!AG31,'Setter 5'!AG31,Rosalie!AG31,'Setter 8'!AG31,'Setter 7'!AG31,'Setter 6'!AG31,Fabien!AG31,'Setter 9'!AG31,'Setter 10'!AG31) -> 0 | AO31: =SUM(David!AO31,Dave!AH31,'Setter 5'!AH31,Rosalie!AH31,'Setter 8'!AH31,'Setter 7'!AH31,'Setter 6'!AH31,Fabien!AH31,'Setter 9'!AH31,'Setter 10'!AH31) -> 0 | AP31: =IFERROR(AO31/AI31,"") | AQ31: =IFERROR(AJ31/AI31,"") | AX31: =T31+B31+AI31 -> 0 | AY31: =AM31+X31+H31 -> 0 | AZ31: =AN31+I31 -> 0 | BA31: =AO31+J31 -> 0 | BB31: =IFERROR(AY31/AX31,"") | BC31: =IFERROR(AZ31/AX31,"") | BD31: =IFERROR(BA31/AX31,"")
